Workbook

Sheet Resumen
A1: Resumen — Criterio: SPECs, Gherkin y TDD (10 pts)
A2: Todas las cifras de esta hoja se calculan con fórmulas sobre la hoja 'Trazabilidad' y la hoja 'Evidencia TDD': edita esas hojas y estos totales se recalculan solos.
A4: Cobertura global de reglas de negocio
A5: Métrica | B5: Valor
A6: Total de reglas de negocio documentadas | B6: =COUNTA(Trazabilidad!D5:D56)
A7: Reglas cubiertas por test (Sí) | B7: =COUNTIF(Trazabilidad!H5:H56,"Sí")
A8: Reglas con cobertura parcial (test sin Gherkin dedicado, o viceversa) | B8: =COUNTIF(Trazabilidad!H5:H56,"Parcial")
A9: Reglas sin cobertura de test (gap real) | B9: =COUNTIF(Trazabilidad!H5:H56,"No")
A10: Reglas no aplicables a test unitario (arquitectónicas / capa SQL / integración) | B10: =COUNTIF(Trazabilidad!H5:H56,"N/A")
A11: % de reglas totalmente cubiertas (Sí / Total) | B11: =B7/B6
A12: % cubierto sobre reglas aplicables a test (Sí / (Total - N/A)) | B12: =B7/(B6-B10)
A14: Cobertura por SPEC
A15: SPEC ID | B15: Reglas totales | C15: Sí | D15: Parcial | E15: No | F15: N/A
A16: SPEC-ANNOT-001 | B16: =COUNTIF(Trazabilidad!A5:A56,A16) | C16: =COUNTIFS(Trazabilidad!A5:A56,A16,Trazabilidad!H5:H56,"Sí") | D16: =COUNTIFS(Trazabilidad!A5:A56,A16,Trazabilidad!H5:H56,"Parcial") | E16: =COUNTIFS(Trazabilidad!A5:A56,A16,Trazabilidad!H5:H56,"No") | F16: =COUNTIFS(Trazabilidad!A5:A56,A16,Trazabilidad!H5:H56,"N/A")
A17: SPEC-COCO-001 | B17: =COUNTIF(Trazabilidad!A5:A56,A17) | C17: =COUNTIFS(Trazabilidad!A5:A56,A17,Trazabilidad!H5:H56,"Sí") | D17: =COUNTIFS(Trazabilidad!A5:A56,A17,Trazabilidad!H5:H56,"Parcial") | E17: =COUNTIFS(Trazabilidad!A5:A56,A17,Trazabilidad!H5:H56,"No") | F17: =COUNTIFS(Trazabilidad!A5:A56,A17,Trazabilidad!H5:H56,"N/A")
A18: SPEC-DASH-001 | B18: =COUNTIF(Trazabilidad!A5:A56,A18) | C18: =COUNTIFS(Trazabilidad!A5:A56,A18,Trazabilidad!H5:H56,"Sí") | D18: =COUNTIFS(Trazabilidad!A5:A56,A18,Trazabilidad!H5:H56,"Parcial") | E18: =COUNTIFS(Trazabilidad!A5:A56,A18,Trazabilidad!H5:H56,"No") | F18: =COUNTIFS(Trazabilidad!A5:A56,A18,Trazabilidad!H5:H56,"N/A")
A19: SPEC-VALID-001 | B19: =COUNTIF(Trazabilidad!A5:A56,A19) | C19: =COUNTIFS(Trazabilidad!A5:A56,A19,Trazabilidad!H5:H56,"Sí") | D19: =COUNTIFS(Trazabilidad!A5:A56,A19,Trazabilidad!H5:H56,"Parcial") | E19: =COUNTIFS(Trazabilidad!A5:A56,A19,Trazabilidad!H5:H56,"No") | F19: =COUNTIFS(Trazabilidad!A5:A56,A19,Trazabilidad!H5:H56,"N/A")
A20: SPEC-UPLOAD-001 | B20: =COUNTIF(Trazabilidad!A5:A56,A20) | C20: =COUNTIFS(Trazabilidad!A5:A56,A20,Trazabilidad!H5:H56,"Sí") | D20: =COUNTIFS(Trazabilidad!A5:A56,A20,Trazabilidad!H5:H56,"Parcial") | E20: =COUNTIFS(Trazabilidad!A5:A56,A20,Trazabilidad!H5:H56,"No") | F20: =COUNTIFS(Trazabilidad!A5:A56,A20,Trazabilidad!H5:H56,"N/A")
A21: SPEC-SEARCH-001 | B21: =COUNTIF(Trazabilidad!A5:A56,A21) | C21: =COUNTIFS(Trazabilidad!A5:A56,A21,Trazabilidad!H5:H56,"Sí") | D21: =COUNTIFS(Trazabilidad!A5:A56,A21,Trazabilidad!H5:H56,"Parcial") | E21: =COUNTIFS(Trazabilidad!A5:A56,A21,Trazabilidad!H5:H56,"No") | F21: =COUNTIFS(Trazabilidad!A5:A56,A21,Trazabilidad!H5:H56,"N/A")
A22: SPEC-COCO-UI-001 | B22: =COUNTIF(Trazabilidad!A5:A56,A22) | C22: =COUNTIFS(Trazabilidad!A5:A56,A22,Trazabilidad!H5:H56,"Sí") | D22: =COUNTIFS(Trazabilidad!A5:A56,A22,Trazabilidad!H5:H56,"Parcial") | E22: =COUNTIFS(Trazabilidad!A5:A56,A22,Trazabilidad!H5:H56,"No") | F22: =COUNTIFS(Trazabilidad!A5:A56,A22,Trazabilidad!H5:H56,"N/A")
A24: Ciclo Red-Green-Refactor
A25: Commits con evidencia RED (ver hoja 'Evidencia TDD') | B25: =COUNTIF('Evidencia TDD'!A5:A12,"RED")
A26: Commits con evidencia GREEN | B26: =COUNTIF('Evidencia TDD'!A5:A12,"GREEN")
A27: Commits con evidencia REFACTOR | B27: =COUNTIF('Evidencia TDD'!A5:A12,"REFACTOR")
A28: Ciclos Red→Green→Refactor completos documentados | B28: =MIN(B25,B26,B27)
A30: Nota: no se ejecutó la suite de tests en este entorno (no hay Node.js/npm instalado); los resultados de cada fase RED/GREEN/REFACTOR en la hoja 'Evidencia TDD' se verificaron leyendo el diff real de cada commit con 'git show', no ejecutando los tests.

Sheet Trazabilidad
A1: Trazabilidad: Regla de negocio → SPEC → Feature (Gherkin) → Test
A2: Portal de Anotación de Imágenes — github.com/karenelizabg/proyecto1 — rama main (HEAD e59ba78) — generado 2026-09-04
A3: Fuente de esta hoja: lectura directa de backend/specs/*.md, backend/features/*.feature, backend/tests/*.test.ts, frontend/src/specs/*.md, frontend/features/*.feature y frontend/tests/*.test.tsx del repositorio (no se ejecutó la suite: no hay Node.js disponible en este entorno; la columna 'Cubierta por test' es análisis estático del código de prueba).
A4: SPEC ID | B4: Módulo | C4: # | D4: Regla de negocio (SPEC) | E4: Escenario(s) Gherkin (Given/When/Then) | F4: Archivo .feature | G4: Archivo de test | H4: Cubierta por test | I4: Nota | J4: Fase / rama de origen
A5: SPEC-ANNOT-001 | B5: Anotación (bounding boxes) | C5: 1 | D5: El origen de la caja debe estar dentro de la imagen (bboxX >= 0 y bboxY >= 0) | E5: Rechazar una caja con origen negativo | F5: backend/features/annotation.feature | G5: backend/tests/annotation.test.ts | H5: Sí | I5: Test cubre bboxX y bboxY negativos por separado; Gherkin solo ilustra bboxX. | J5: Fase 4 — rama stage4-glue (PR #6, commit 1584b00, 2026-09-03)
A6: SPEC-ANNOT-001 | B6: Anotación (bounding boxes) | C6: 2 | D6: Las dimensiones deben ser positivas (bboxWidth > 0 y bboxHeight > 0) | E6: Rechazar una caja con dimensiones cero o negativas | F6: backend/features/annotation.feature | G6: backend/tests/annotation.test.ts | H6: Sí | J6: Fase 4 — rama stage4-glue (PR #6, commit 1584b00, 2026-09-03)
A7: SPEC-ANNOT-001 | B7: Anotación (bounding boxes) | C7: 3 | D7: La caja no puede salirse del canvas (bboxX+bboxWidth<=width, bboxY+bboxHeight<=height) | E7: Rechazar una caja que excede el ancho / el alto de la imagen | F7: backend/features/annotation.feature | G7: backend/tests/annotation.test.ts | H7: Sí | J7: Fase 4 — rama stage4-glue (PR #6, commit 1584b00, 2026-09-03)
A8: SPEC-ANNOT-001 | B8: Anotación (bounding boxes) | C8: 4 | D8: El categoryId debe referirse a una categoría existente en la base de datos | E8: Rechazar una caja sin categoría válida (categoryId <= 0) | F8: backend/features/annotation.feature | G8: backend/tests/annotation.test.ts | H8: Parcial | I8: El test solo valida que categoryId sea un entero positivo (forma). No hay assertCategoryExists real ni test de integración que verifique existencia en BD. | J8: Fase 4 — rama stage4-glue (PR #6, commit 1584b00, 2026-09-03)
A9: SPEC-ANNOT-001 | B9: Anotación (bounding boxes) | C9: 5 | D9: El área se calcula en backend (area = bboxWidth × bboxHeight); el cliente nunca la envía | E9: Aceptar una bounding box válida dentro del canvas | F9: backend/features/annotation.feature | G9: backend/tests/annotation.test.ts | H9: Sí | J9: Fase 4 — rama stage4-glue (PR #6, commit 1584b00, 2026-09-03)
A10: SPEC-ANNOT-001 | B10: Anotación (bounding boxes) | C10: 6 | D10: Si la validación falla, la anotación no debe persistirse | E10: (implícita en los escenarios de rechazo anteriores) | F10: backend/features/annotation.feature | G10: backend/tests/annotation.test.ts | H10: Sí | J10: Fase 4 — rama stage4-glue (PR #6, commit 1584b00, 2026-09-03)
A11: SPEC-ANNOT-001 | B11: Anotación (bounding boxes) | C11: 7 | D11: Ninguna caja puede quedar sin categoría válida | E11: Rechazar una caja sin categoría válida (categoryId <= 0) | F11: backend/features/annotation.feature | G11: backend/tests/annotation.test.ts | H11: Parcial | I11: Misma limitación que la regla 4: solo se prueba la forma, no la existencia real. | J11: Fase 4 — rama stage4-glue (PR #6, commit 1584b00, 2026-09-03)
A12: SPEC-ANNOT-001 | B12: Anotación (bounding boxes) | C12: 8 | D12: Al crear la primera bounding box en una imagen pending, esta pasa a in_progress | E12: — sin escenario Gherkin — | F12: backend/features/annotation.feature | G12: — sin test — | H12: No | I12: GAP REAL. Implementado en src/logic/annotation.service.ts (líneas 92-95) pero depende de la BD real (findImageById/updateImageStatus); no existe test unitario ni de integración ni escenario Gherkin. | J12: Fase 4 — rama stage4-glue (PR #6, commit 1584b00, 2026-09-03)
A13: SPEC-ANNOT-001 | B13: Anotación (bounding boxes) | C13: 9 | D13: Al eliminar todas las cajas de una imagen no pending, su status vuelve a pending | E13: — sin escenario Gherkin — | F13: backend/features/annotation.feature | G13: — sin test — | H13: No | I13: GAP REAL. Implementado en deleteAnnotation() (annotation.service.ts líneas 166-181) pero sin ninguna cobertura de prueba. | J13: Fase 4 — rama stage4-glue (PR #6, commit 1584b00, 2026-09-03)
A14: SPEC-ANNOT-001 | B14: Anotación (bounding boxes) | C14: 10 | D14: El usuario debe pulsar "Finalizar" explícitamente para pasar a completed (no se autocompleta) | E14: — sin escenario Gherkin — | F14: backend/features/annotation.feature | G14: — sin test — | H14: No | I14: GAP REAL. setImageStatus() (image-status.service.ts) exige al menos 1 anotación para completar, pero no hay test que lo verifique. | J14: Fase 4 — rama stage4-glue (PR #6, commit 1584b00, 2026-09-03)
A15: SPEC-ANNOT-001 | B15: Anotación (bounding boxes) | C15: 11 | D15: Una imagen completed no puede completarse de nuevo (idempotente) | E15: — sin escenario Gherkin — | F15: backend/features/annotation.feature | G15: — sin test — | H15: No | I15: GAP REAL. La idempotencia está implementada (image-status.service.ts línea 31-33: if image.status === nextStatus return) pero sin test que la ejercite. | J15: Fase 4 — rama stage4-glue (PR #6, commit 1584b00, 2026-09-03)
A16: SPEC-COCO-001 | B16: Exportación COCO | C16: 1 | D16: El documento COCO tiene exactamente las secciones images, annotations y categories | E16: El JSON tiene las tres secciones obligatorias | F16: backend/features/coco-export.feature | G16: backend/tests/coco-export.test.ts | H16: Sí | J16: Fase 4 — rama stage4-glue (PR #6, commit 1584b00, 2026-09-03)
A17: SPEC-COCO-001 | B17: Exportación COCO | C17: 2 | D17: El bbox se serializa en el orden exacto [x, y, width, height] en píxeles absolutos | E17: Cada anotación usa el bbox en orden [x, y, width, height] | F17: backend/features/coco-export.feature | G17: backend/tests/coco-export.test.ts | H17: Sí | J17: Fase 4 — rama stage4-glue (PR #6, commit 1584b00, 2026-09-03)
A18: SPEC-COCO-001 | B18: Exportación COCO | C18: 3 | D18: El área es coherente: area === bbox[2] × bbox[3] | E18: El área de cada anotación es coherente con el bbox | F18: backend/features/coco-export.feature | G18: backend/tests/coco-export.test.ts | H18: Sí | J18: Fase 4 — rama stage4-glue (PR #6, commit 1584b00, 2026-09-03)
A19: SPEC-COCO-001 | B19: Exportación COCO | C19: 4 | D19: El campo iscrowd siempre debe estar presente, con valor 0 o 1 | E19: El campo iscrowd siempre está presente como 0 o 1 | F19: backend/features/coco-export.feature | G19: backend/tests/coco-export.test.ts | H19: Sí | I19: Test cubre además el caso isCrowd=true -> 1 (no ilustrado en Gherkin). | J19: Fase 4 — rama stage4-glue (PR #6, commit 1584b00, 2026-09-03)
A20: SPEC-COCO-001 | B20: Exportación COCO | C20: 5 | D20: Todo annotations[].image_id y category_id debe existir en images[] / categories[] | E20: Los IDs son consistentes entre secciones | F20: backend/features/coco-export.feature | G20: backend/tests/coco-export.test.ts | H20: Sí | J20: Fase 4 — rama stage4-glue (PR #6, commit 1584b00, 2026-09-03)
A21: SPEC-COCO-001 | B21: Exportación COCO | C21: 6 | D21: La exportación incluye todas las imágenes, incluso las que no tienen anotaciones | E21: Las imágenes sin anotaciones también se incluyen | F21: backend/features/coco-export.feature | G21: backend/tests/coco-export.test.ts | H21: Sí | J21: Fase 4 — rama stage4-glue (PR #6, commit 1584b00, 2026-09-03)
A22: SPEC-DASH-001 | B22: Métricas del dashboard | C22: 1 | D22: imagesUploaded es el total de imágenes registradas, sumando todos los estados | E22: El total de imágenes suma todos los estados | F22: backend/features/dashboard.feature | G22: backend/tests/dashboard.test.ts | H22: Sí | J22: Fase 4 — rama stage4-glue (PR #6, commit 1584b00, 2026-09-03)
A23: SPEC-DASH-001 | B23: Métricas del dashboard | C23: 2 | D23: imagesAnnotated cuenta únicamente las imágenes en estado completed | E23: Solo las completadas cuentan como anotadas | F23: backend/features/dashboard.feature | G23: backend/tests/dashboard.test.ts | H23: Sí | J23: Fase 4 — rama stage4-glue (PR #6, commit 1584b00, 2026-09-03)
A24: SPEC-DASH-001 | B24: Métricas del dashboard | C24: 3 | D24: boundingBoxes es el total de anotaciones del dataset | E24: — sin escenario Gherkin dedicado — | F24: backend/features/dashboard.feature | G24: backend/tests/dashboard.test.ts | H24: Parcial | I24: Cubierto por test ('refleja el total de bounding boxes') pero sin escenario Gherkin propio. | J24: Fase 4 — rama stage4-glue (PR #6, commit 1584b00, 2026-09-03)
A25: SPEC-DASH-001 | B25: Métricas del dashboard | C25: 4 | D25: categoriesCount es el total de categorías registradas | E25: — sin escenario Gherkin dedicado — | F25: backend/features/dashboard.feature | G25: backend/tests/dashboard.test.ts | H25: Parcial | I25: Cubierto por test ('refleja el total de categorías') pero sin escenario Gherkin propio. | J25: Fase 4 — rama stage4-glue (PR #6, commit 1584b00, 2026-09-03)
A26: SPEC-DASH-001 | B26: Métricas del dashboard | C26: 5 | D26: objectsPerClass agrupa por categoría con name/color persistidos; excluye categorías sin anotaciones | E26: Los objetos por clase conservan nombre y color | F26: backend/features/dashboard.feature | G26: backend/tests/dashboard.test.ts | H26: Parcial | I26: El test verifica name/color/count, pero ningún test/escenario verifica que una categoría sin anotaciones quede excluida. | J26: Fase 4 — rama stage4-glue (PR #6, commit 1584b00, 2026-09-03)
A27: SPEC-DASH-001 | B27: Métricas del dashboard | C27: 6 | D27: annotationProgress.annotated = completed; .pending = pending + in_progress | E27: El progreso separa lo terminado de lo pendiente | F27: backend/features/dashboard.feature | G27: backend/tests/dashboard.test.ts | H27: Sí | J27: Fase 4 — rama stage4-glue (PR #6, commit 1584b00, 2026-09-03)
A28: SPEC-DASH-001 | B28: Métricas del dashboard | C28: 7 | D28: La suma annotated + pending debe ser igual a imagesUploaded | E28: El progreso siempre cuadra con el total | F28: backend/features/dashboard.feature | G28: backend/tests/dashboard.test.ts | H28: Sí | J28: Fase 4 — rama stage4-glue (PR #6, commit 1584b00, 2026-09-03)
A29: SPEC-DASH-001 | B29: Métricas del dashboard | C29: 8 | D29: recentUploads usa la URL del binario servida por el backend, nunca una URL de MinIO | E29: Las miniaturas se sirven por el backend | F29: backend/features/dashboard.feature | G29: backend/tests/dashboard.test.ts | H29: Sí | J29: Fase 4 — rama stage4-glue (PR #6, commit 1584b00, 2026-09-03)
A30: SPEC-DASH-001 | B30: Métricas del dashboard | C30: 9 | D30: Todos los conteos provienen de COUNT / GROUP BY en SQL (no se filtra en memoria) | E30: — no aplica a un test unitario — | F30: backend/features/dashboard.feature | G30: — | H30: N/A | I30: Regla de la capa Data (agregados SQL reales); el builder probado es una función pura que ya recibe los agregados calculados. | J30: Fase 4 — rama stage4-glue (PR #6, commit 1584b00, 2026-09-03)
A31: SPEC-VALID-001 | B31: Validación HTTP (Zod) | C31: 1 | D31: Body de POST /annotations (createAnnotationSchema): rechaza imageId nulo/no numérico/cero/negativo/ausente y body vacío; acepta uno válido | E31: Rechazar imageId nulo / no número / body vacío / imageId cero o negativo; Aceptar un body de anotación completo y válido | F31: backend/features/http-validation.feature | G31: backend/tests/http-validation.test.ts | H31: Sí | J31: Fase 4 — rama stage4-glue (PR #6, commit 1584b00, 2026-09-03)
A32: SPEC-VALID-001 | B32: Validación HTTP (Zod) | C32: 2 | D32: Body de PATCH /annotations/:id (updateAnnotationSchema) | E32: — sin escenario Gherkin dedicado — | F32: backend/features/http-validation.feature | G32: backend/tests/http-validation.test.ts | H32: Parcial | I32: 3 tests cubren updateAnnotationSchema, pero el .feature no tiene escenarios para esta frontera. | J32: Fase 4 — rama stage4-glue (PR #6, commit 1584b00, 2026-09-03)
A33: SPEC-VALID-001 | B33: Validación HTTP (Zod) | C33: 3 | D33: Body de PATCH /images/:id/status (imageStatusSchema): solo acepta el enum pending/in_progress/completed | E33: Rechazar un status que no pertenece al enum / con texto arbitrario; Aceptar los tres estados válidos | F33: backend/features/http-validation.feature | G33: backend/tests/http-validation.test.ts | H33: Sí | J33: Fase 4 — rama stage4-glue (PR #6, commit 1584b00, 2026-09-03)
A34: SPEC-VALID-001 | B34: Validación HTTP (Zod) | C34: 4 | D34: Route param :id (idParamSchema): entero positivo, se convierte a number | E34: Rechazar un route param que no es entero positivo / el route param cero; Aceptar y convertir un route param numérico | F34: backend/features/http-validation.feature | G34: backend/tests/http-validation.test.ts | H34: Sí | J34: Fase 4 — rama stage4-glue (PR #6, commit 1584b00, 2026-09-03)
A35: SPEC-VALID-001 | B35: Validación HTTP (Zod) | C35: 5 | D35: Query params de GET /images/search (imageSearchSchema) | E35: — sin escenario Gherkin — | F35: backend/features/http-validation.feature | G35: — sin test — | H35: No | I35: GAP REAL. imageSearchSchema existe en src/logic/annotation.validation.ts (líneas 193-225) pero ningún test ni escenario Gherkin lo ejercita directamente. | J35: Fase 4 — rama stage4-glue (PR #6, commit 1584b00, 2026-09-03)
A36: SPEC-VALID-001 | B36: Validación HTTP (Zod) | C36: 6 | D36: Variables de entorno (envSchema) | E36: — sin escenario Gherkin — | F36: backend/features/http-validation.feature | G36: — sin test — | H36: No | I36: GAP REAL. envSchema existe en src/config/env.ts pero no tiene test ni escenario Gherkin. | J36: Fase 4 — rama stage4-glue (PR #6, commit 1584b00, 2026-09-03)
A37: SPEC-UPLOAD-001 | B37: Carga de imágenes | C37: 1 | D37: Solo se aceptan archivos de imagen con tipos MIME permitidos (jpeg/png/webp) | E37: Aceptar una imagen JPEG válida; Rechazar un archivo que no sea imagen | F37: backend/features/image-upload.feature | G37: backend/tests/image-upload.test.ts | H37: Sí | I37: Ciclo TDD completo documentado en la hoja 'Evidencia TDD' (commits d52b307 / 0dfe05b / cd6e011). | J37: Fase 2 — rama backend/stage2-minio (PR #1, commit d52b307, 2026-08-31)
A38: SPEC-UPLOAD-001 | B38: Carga de imágenes | C38: 2 | D38: El archivo debe respetar el tamaño máximo configurado | E38: Rechazar una imagen demasiado grande | F38: backend/features/image-upload.feature | G38: backend/tests/image-upload.test.ts | H38: Sí | J38: Fase 2 — rama backend/stage2-minio (PR #1, commit d52b307, 2026-08-31)
A39: SPEC-UPLOAD-001 | B39: Carga de imágenes | C39: 3 | D39: Una imagen válida debe almacenarse en MinIO | E39: — requiere integración real con MinIO — | F39: backend/features/image-upload.feature | G39: — | H39: No | I39: No cubierto por test unitario; requeriría test de integración contra un MinIO real o en memoria. | J39: Fase 2 — rama backend/stage2-minio (PR #1, commit d52b307, 2026-08-31)
A40: SPEC-UPLOAD-001 | B40: Carga de imágenes | C40: 4 | D40: Los metadatos de la imagen deben almacenarse en MariaDB | E40: — requiere integración real con MariaDB — | F40: backend/features/image-upload.feature | G40: — | H40: No | I40: No cubierto por test unitario; requeriría test de integración contra la base de datos. | J40: Fase 2 — rama backend/stage2-minio (PR #1, commit d52b307, 2026-08-31)
...

Sheet Evidencia TDD
A1: Evidencia de ciclo Red → Green → Refactor en el historial de commits
A2: Repositorio: github.com/karenelizabg/proyecto1 — verificado con 'git show <hash>' y 'git show --stat <hash>' sobre el historial real de la rama main. Se documentan los dos ciclos TDD explícitos encontrados en el historial.
A4: Fase | B4: Commit | C4: Fecha | D4: Mensaje | E4: Archivos modificados | F4: Líneas +/- | G4: Resultado al ejecutar la suite / evidencia en el diff
A5: RED | B5: d52b307 | C5: 2026-08-31 06:39 | D5: test: add failing image upload validation scenarios | E5: features/image-upload.feature (+22, nuevo); specs/image-upload.spec.md (+25, nuevo); src/logic/image-upload.validation.ts (nuevo, stub); tests/image-upload.test.ts (nuevo, 3 tests) | F5: +114 / -0 | G5: FALLA (por diseño): validateImageUpload() es un stub que siempre retorna {success:false}. El test 'acepta una imagen JPEG válida' espera success=true y falla.
A6: GREEN | B6: 0dfe05b | C6: 2026-08-31 06:42 | D6: feat: implement image upload validation | E6: src/logic/image-upload.validation.ts (+22 / -10) | F6: +22 / -10 | G6: PASA: se reemplaza el stub por un schema Zod real (enum de MIME permitidos + límite de tamaño). Los 3 tests de tests/image-upload.test.ts pasan.
A7: REFACTOR | B7: cd6e011 | C7: 2026-08-31 06:45 | D7: refactor: extract image upload schema creation | E7: src/logic/image-upload.validation.ts (+11 / -5) | F7: +11 / -5 | G7: SIGUE EN VERDE: se extrae createImageUploadSchema(maxSizeBytes) como función independiente, sin tocar la lógica de validación ni las aserciones de los tests.
A9: RED | B9: 91b5540 | C9: 2026-09-04 22:44 | D9: test(frontend): add failing COCO export button scenarios | E9: frontend/tests/dashboard-export.test.tsx (nuevo, 2 tests); frontend/src/test/setup.ts, frontend/tsconfig.json, frontend/vitest.config.ts (config de test) | F9: +1533 / -9 (incluye dependencias de testing agregadas) | G9: FALLA (por diseño): DashboardPage no tiene ningún link 'Exportar COCO'. screen.getByRole('link', {name:/exportar coco/i}) no encuentra el elemento en ambos tests.
A10: GREEN | B10: a58d6fd | C10: 2026-09-04 22:53 | D10: feat(frontend): enable COCO dataset download | E10: frontend/src/pages/Dashboard.tsx (+9 / -1); frontend/tests/dashboard-export.test.tsx (+18 / -2) | F10: +24 / -3 | G10: PASA: se agrega el <a href="/api/export/coco"> con el ícono Download y el texto 'Exportar COCO'. Los 2 tests de dashboard-export.test.tsx pasan.
A11: REFACTOR | B11: 1aa3792 | C11: 2026-09-04 23:07 | D11: refactor(frontend): reuse configured API URL for COCO export | E11: frontend/src/api/client.ts (+8 / -1, nueva función buildApiUrl); frontend/src/pages/Dashboard.tsx (+2 / -1) | F11: +10 / -2 | G11: SIGUE EN VERDE: se reemplaza la URL hardcodeada '/api/export/coco' por buildApiUrl('/export/coco'), reutilizando la misma configuración de VITE_API_BASE_URL que el resto del cliente HTTP. Sin cambio de comportamiento observable; los 2 tests siguen pasando.
A12: TEST (post-refactor) | B12: c0b451f | C12: 2026-09-04 23:18 | D12: test(frontend): simplify COCO export test setup | E12: frontend/tests/dashboard-export.test.tsx (+10 / -11) | F12: +10 / -11 | G12: Limpieza del setup del test (afterEach/cleanup de Testing Library) sin alterar las aserciones ni el resultado.
A14: Nota: ambos ciclos están presentes en el historial de commits de la rama main (no se han rebaseado ni squasheado). El primer ciclo (image upload) es previo a la reorganización del backend en la carpeta backend/, por eso sus rutas no llevan ese prefijo.
